Workbook

Sheet Tabelle1
B1: V1 (Serie, lang)
B2: Pflanzen-Nr. | C2: Ablage-Tiefe | D2: Mittelwert | E2: Standartabweichung | F2: Q5 | G2: Q95 | H2: Position Saatgut | I2: Abstand zum vorherigen Saatgut
B3: 1 | C3: -40 | D3: -32.334025 | E3: =_xlfn.STDEV.P($C$3:$C$484) -> 7.3254547 | F3: -20 | G3: -42 | H3: 0
B4: 2 | C4: -40 | D4: -32.334025 | E4: =_xlfn.STDEV.P($C$3:$C$484) -> 7.3254547 | F4: -20 | G4: -42 | H4: 34 | I4: 34
B5: 3 | C5: -40 | D5: -32.334025 | E5: =_xlfn.STDEV.P($C$3:$C$484) -> 7.3254547 | F5: -20 | G5: -42 | H5: 52.7 | I5: 18.7
B6: 4 | C6: -45 | D6: -32.334025 | E6: =_xlfn.STDEV.P($C$3:$C$484) -> 7.3254547 | F6: -20 | G6: -42 | H6: 88.9 | I6: 36.2 | K6: Hier sehen sie Messergebnisse bei denen auf 15 Meter (Insgesamt 482 Pflanzen) die Saatkörner auf die Aussaattiefe bemessen wurden.
B7: 5 | C7: -40 | D7: -32.334025 | E7: =_xlfn.STDEV.P($C$3:$C$484) -> 7.3254547 | F7: -20 | G7: -42 | H7: 98.5 | I7: 9.6
B8: 6 | C8: -40 | D8: -32.334025 | E8: =_xlfn.STDEV.P($C$3:$C$484) -> 7.3254547 | F8: -20 | G8: -42 | H8: 160.6 | I8: 62.1 | K8: Ich versuche jetzt herauszufinden, wie viel Körner ich bemessen muss um ein annähernd belastbares Ergebnis zu bekommen
B9: 7 | C9: -40 | D9: -32.334025 | E9: =_xlfn.STDEV.P($C$3:$C$484) -> 7.3254547 | F9: -20 | G9: -42 | H9: 168.5 | I9: 7.9 | K9: Selbstverständlich ist es umso genauer, wenn ich möglichst viele Körner auf Ablagetiefe messe.
B10: 8 | C10: -30 | D10: -32.334025 | E10: =_xlfn.STDEV.P($C$3:$C$484) -> 7.3254547 | F10: -20 | G10: -42 | H10: 178.9 | I10: 10.4
B11: 9 | C11: -35 | D11: -32.334025 | E11: =_xlfn.STDEV.P($C$3:$C$484) -> 7.3254547 | F11: -20 | G11: -42 | H11: 189.4 | I11: 10.5 | K11: Ich versuche herauszufinden wie hoch die Differenz ist, wenn ich nur 25 Körner bemesse anstatt 50 Körner.
B12: 10 | C12: -33 | D12: -32.334025 | E12: =_xlfn.STDEV.P($C$3:$C$484) -> 7.3254547 | F12: -20 | G12: -42 | H12: 199 | I12: 9.6
B13: 11 | C13: -37 | D13: -32.334025 | E13: =_xlfn.STDEV.P($C$3:$C$484) -> 7.3254547 | F13: -20 | G13: -42 | H13: 208 | I13: 9 | K13: Hierfür bin ich angefangen die Mittelwerte aus 25er Schritten und 50er Schritten zu binden und miteinander zu vergleichen
B14: 12 | C14: -15 | D14: -32.334025 | E14: =_xlfn.STDEV.P($C$3:$C$484) -> 7.3254547 | F14: -20 | G14: -42 | H14: 228.8 | I14: 20.8
B15: 13 | C15: -30 | D15: -32.334025 | E15: =_xlfn.STDEV.P($C$3:$C$484) -> 7.3254547 | F15: -20 | G15: -42 | H15: 292.9 | I15: 64.1
B16: 14 | C16: -35 | D16: -32.334025 | E16: =_xlfn.STDEV.P($C$3:$C$484) -> 7.3254547 | F16: -20 | G16: -42 | H16: 418.6 | I16: 125.7
B17: 15 | C17: -30 | D17: -32.334025 | E17: =_xlfn.STDEV.P($C$3:$C$484) -> 7.3254547 | F17: -20 | G17: -42 | H17: 431.4 | I17: 12.8
B18: 16 | C18: -40 | D18: -32.334025 | E18: =_xlfn.STDEV.P($C$3:$C$484) -> 7.3254547 | F18: -20 | G18: -42 | H18: 454.6 | I18: 23.2
B19: 17 | C19: -30 | D19: -32.334025 | E19: =_xlfn.STDEV.P($C$3:$C$484) -> 7.3254547 | F19: -20 | G19: -42 | H19: 536.1 | I19: 81.5
B20: 18 | C20: -42 | D20: -32.334025 | E20: =_xlfn.STDEV.P($C$3:$C$484) -> 7.3254547 | F20: -20 | G20: -42 | H20: 561.9 | I20: 25.8 | K20: 50er Schritte | M20: Mittelwert | N20: Differenz
B21: 19 | C21: -42 | D21: -32.334025 | E21: =_xlfn.STDEV.P($C$3:$C$484) -> 7.3254547 | F21: -20 | G21: -42 | H21: 565.9 | I21: 4
B22: 20 | C22: -40 | D22: -32.334025 | E22: =_xlfn.STDEV.P($C$3:$C$484) -> 7.3254547 | F22: -20 | G22: -42 | H22: 601.2 | I22: 35.3 | K22: 0-50 | M22: =AVERAGE(Tabelle1!C3:C52) -> -32.98 | N22: =ABS(M22-$D$3) -> 0.6459751
B23: 21 | C23: -30 | D23: -32.334025 | E23: =_xlfn.STDEV.P($C$3:$C$484) -> 7.3254547 | F23: -20 | G23: -42 | H23: 644.7 | I23: 43.5 | K23: 51-100 | M23: =AVERAGE(Tabelle1!C53:C102) -> -32.78 | N23: =ABS(M23-$D$3) -> 0.4459751
B24: 22 | C24: -40 | D24: -32.334025 | E24: =_xlfn.STDEV.P($C$3:$C$484) -> 7.3254547 | F24: -20 | G24: -42 | H24: 688.4 | I24: 43.7 | K24: 101-150 | M24: =AVERAGE(Tabelle1!C103:C152) -> -35.24 | N24: =ABS(M24-$D$3) -> 2.9059751
B25: 23 | C25: -41 | D25: -32.334025 | E25: =_xlfn.STDEV.P($C$3:$C$484) -> 7.3254547 | F25: -20 | G25: -42 | H25: 705 | I25: 16.6 | K25: 151-200 | M25: =AVERAGE(Tabelle1!C153:C202) -> -29.34 | N25: =ABS(M25-$D$3) -> 2.9940249
B26: 24 | C26: -33 | D26: -32.334025 | E26: =_xlfn.STDEV.P($C$3:$C$484) -> 7.3254547 | F26: -20 | G26: -42 | H26: 706.8 | I26: 1.8 | K26: 201-250 | M26: =AVERAGE(Tabelle1!C203:C252) -> -35.3 | N26: =ABS(M26-$D$3) -> 2.9659751
B27: 25 | C27: -35 | D27: -32.334025 | E27: =_xlfn.STDEV.P($C$3:$C$484) -> 7.3254547 | F27: -20 | G27: -42 | H27: 753.2 | I27: 46.4 | K27: 251-300 | M27: =AVERAGE(Tabelle1!C253:C302) -> -32.2 | N27: =ABS(M27-$D$3) -> 0.1340249
B28: 26 | C28: -27 | D28: -32.334025 | E28: =_xlfn.STDEV.P($C$3:$C$484) -> 7.3254547 | F28: -20 | G28: -42 | H28: 768.2 | I28: 15 | K28: 301-350 | M28: =AVERAGE(Tabelle1!C303:C352) -> -28.22 | N28: =ABS(M28-$D$3) -> 4.1140249
B29: 27 | C29: -22 | D29: -32.334025 | E29: =_xlfn.STDEV.P($C$3:$C$484) -> 7.3254547 | F29: -20 | G29: -42 | H29: 849.4 | I29: 81.2 | K29: 351-400 | M29: =AVERAGE(Tabelle1!C353:C402) -> -32.26 | N29: =ABS(M29-$D$3) -> 0.074024896
B30: 28 | C30: -28 | D30: -32.334025 | E30: =_xlfn.STDEV.P($C$3:$C$484) -> 7.3254547 | F30: -20 | G30: -42 | H30: 853.9 | I30: 4.5 | K30: 401-450 | M30: =AVERAGE(Tabelle1!C403:C452) -> -32.14 | N30: =ABS(M30-$D$3) -> 0.1940249
B31: 29 | C31: -35 | D31: -32.334025 | E31: =_xlfn.STDEV.P($C$3:$C$484) -> 7.3254547 | F31: -20 | G31: -42 | H31: 854 | I31: 0.1 | K31: 451-482 | M31: =AVERAGE(Tabelle1!C453:C484) -> -33.1875 | N31: =ABS(M31-$D$3) -> 0.8534751
B32: 30 | C32: -28 | D32: -32.334025 | E32: =_xlfn.STDEV.P($C$3:$C$484) -> 7.3254547 | F32: -20 | G32: -42 | H32: 864.8 | I32: 10.8
B33: 31 | C33: -25 | D33: -32.334025 | E33: =_xlfn.STDEV.P($C$3:$C$484) -> 7.3254547 | F33: -20 | G33: -42 | H33: 899.8 | I33: 35 | M33: Mittelwert | N33: =AVERAGE(N22:N31) -> 1.53275
B34: 32 | C34: -27 | D34: -32.334025 | E34: =_xlfn.STDEV.P($C$3:$C$484) -> 7.3254547 | F34: -20 | G34: -42 | H34: 909.5 | I34: 9.7
B35: 33 | C35: -25 | D35: -32.334025 | E35: =_xlfn.STDEV.P($C$3:$C$484) -> 7.3254547 | F35: -20 | G35: -42 | H35: 936.5 | I35: 27 | K35: 25er Schritte | M35: Mittelwert | N35: Differenz
B36: 34 | C36: -22 | D36: -32.334025 | E36: =_xlfn.STDEV.P($C$3:$C$484) -> 7.3254547 | F36: -20 | G36: -42 | H36: 946.4 | I36: 9.9
B37: 35 | C37: -30 | D37: -32.334025 | E37: =_xlfn.STDEV.P($C$3:$C$484) -> 7.3254547 | F37: -20 | G37: -42 | H37: 991 | I37: 44.6 | K37: 0-25 | M37: =AVERAGE(Tabelle1!C3:C27) -> -36.12 | N37: =ABS(M37-$D$3) -> 3.7859751
B38: 36 | C38: -20 | D38: -32.334025 | E38: =_xlfn.STDEV.P($C$3:$C$484) -> 7.3254547 | F38: -20 | G38: -42 | H38: 1002.8 | I38: 11.8 | K38: 26-51 | M38: =AVERAGE(Tabelle1!C28:C52) -> -29.84 | N38: =ABS(M38-$D$3) -> 2.4940249
B39: 37 | C39: -27 | D39: -32.334025 | E39: =_xlfn.STDEV.P($C$3:$C$484) -> 7.3254547 | F39: -20 | G39: -42 | H39: 1025 | I39: 22.2 | K39: 52-77 | M39: =AVERAGE(Tabelle1!C53:C78) -> -34 | N39: =ABS(M39-$D$3) -> 1.6659751
B40: 38 | C40: -15 | D40: -32.334025 | E40: =_xlfn.STDEV.P($C$3:$C$484) -> 7.3254547 | F40: -20 | G40: -42 | H40: 1117 | I40: 92 | K40: 78-103 | M40: =AVERAGE(Tabelle1!C79:C104) -> -31.153846 | N40: =ABS(M40-$D$3) -> 1.1801787
...
